Workbook

Sheet BD
A1: Nombre del empleado | B1: ID | C1: Puntuación rendimiento ID | D1: Salario mensual corregido | E1: Cargo | F1: Fecha de Nacimiento | G1: Sexo | H1: Estado Civil | I1: Fecha de Contratación | J1: Fecha de Salida | K1: Motivo Salida | L1: Estado de miembro | M1: Departamento | N1: Fuente Reclutamiento | O1: Registro de rendimiento | P1: Encuesta de compromiso | Q1: Índice de Satisfacción | R1: SpecialProjectsCount | S1: Última atualización de rendimiento | T1: Tiempo Medio Años
A2: Agustina Morales | B2: 1304055947 | C2: 4 | D2: 5060 | E2: Técnico de Producción I | F2: 30092 | G2: F | H2: Soltero | I2: 43709 | K2: N/A - Empleado | L2: Activo | M2: Producción | N2: Web de la Empresa | O2: Por encima de lo Esperado | P2: 5 | Q2: 5 | R2: 0 | S2: 44166 | T2: =IF(L2="Activo",(DATE(2024,1,1)-I2)/365,(J2-I2)/365) -> 4.3369863
A3: Lucas Figueroa | B3: 1109029366 | C3: 3 | D3: 3520 | E3: Técnico de Producción I | F3: 27749 | G3: M | H3: Soltero | I3: 43499 | K3: N/A - Empleado | L3: Activo | M3: Producción | N3: Indicación de empleados | O3: Dentro de lo Esperado | P3: 5 | Q3: 3 | R3: 0 | S3: 44166 | T3: =IF(L3="Activo",(DATE(2024,1,1)-I3)/365,(J3-I3)/365) -> 4.9123288
A4: Marcos Rodríguez | B4: 1501072124 | C4: 1 | D4: 4400 | E4: Técnico de Producción I | F4: 26406 | G4: M | H4: Casado(a) | I4: 44383 | K4: N/A - Empleado | L4: Activo | M4: Producción | N4: Web de empleo | O4: Por debajo de lo esperado | P4: 1.12 | Q4: 2 | R4: 0 | S4: 44166 | T4: =IF(L4="Activo",(DATE(2024,1,1)-I4)/365,(J4-I4)/365) -> 2.490411
A5: Juan Pérez | B5: 1302053339 | C5: 1 | D5: 3960 | E5: Técnico de Producción I | F5: 34624 | G5: M | H5: Casado(a) | I5: 44869 | K5: N/A - Empleado | L5: Activo | M5: Producción | N5: Web de empleo | O5: Por debajo de lo esperado | P5: 1.56 | Q5: 4 | R5: 0 | S5: 44166 | T5: =IF(L5="Activo",(DATE(2024,1,1)-I5)/365,(J5-I5)/365) -> 1.1589041
A6: Lucía Fernández | B6: 1204032927 | C6: 4 | D6: 3520 | E6: Técnico de Producción I | F6: 31263 | G6: F | H6: Soltero | I6: 44467 | K6: N/A - Empleado | L6: Activo | M6: Producción | N6: Feria de empleo | O6: Por encima de lo Esperado | P6: 3.39 | Q6: 4 | R6: 0 | S6: 44166 | T6: =IF(L6="Activo",(DATE(2024,1,1)-I6)/365,(J6-I6)/365) -> 2.260274
A7: Emma López | B7: 1404066622 | C7: 4 | D7: 4400 | E7: Técnico de Producción I | F7: 28890 | G7: F | H7: Casado(a) | I7: 44534 | K7: N/A - Empleado | L7: Activo | M7: Producción | N7: Web de empleo | O7: Por encima de lo Esperado | P7: 4.76 | Q7: 4 | R7: 0 | S7: 44166 | T7: =IF(L7="Activo",(DATE(2024,1,1)-I7)/365,(J7-I7)/365) -> 2.0767123
A8: Sofía Ramírez | B8: 1205033102 | C8: 3 | D8: 3300 | E8: Técnico de Producción I | F8: 33108 | G8: F | H8: Casado(a) | I8: 44061 | K8: N/A - Empleado | L8: Activo | M8: Producción | N8: Web de empleo | O8: Dentro de lo Esperado | P8: 4.81 | Q8: 4 | R8: 0 | S8: 44166 | T8: =IF(L8="Activo",(DATE(2024,1,1)-I8)/365,(J8-I8)/365) -> 3.3726027
A9: Lisa Sánchez | B9: 1308060366 | C9: 4 | D9: 3520 | E9: Técnico de Producción I | F9: 34342 | G9: F | H9: Casado(a) | I9: 44383 | K9: N/A - Empleado | L9: Activo | M9: Producción | N9: Feria de empleo | O9: Por encima de lo Esperado | P9: 5 | Q9: 3.1 | R9: 0 | S9: 44166 | T9: =IF(L9="Activo",(DATE(2024,1,1)-I9)/365,(J9-I9)/365) -> 2.490411
A10: Valerio Romero | B10: 1407069280 | C10: 4 | D10: 5445 | E10: Técnico de Producción I | F10: 31284 | G10: M | H10: Casado(a) | I10: 45084 | K10: N/A - Empleado | L10: Activo | M10: Producción | N10: Indicación de empleados | O10: Por encima de lo Esperado | P10: 1.97 | Q10: 4 | R10: 0 | S10: 44166 | T10: =IF(L10="Activo",(DATE(2024,1,1)-I10)/365,(J10-I10)/365) -> 0.56986301
A11: Hanna Torres | B11: 1209048696 | C11: 2 | D11: 4840 | E11: Técnico de Producción I | F11: 30358 | G11: F | H11: Casado(a) | I11: 44012 | K11: N/A - Empleado | L11: Activo | M11: Producción | N11: Web de empleo | O11: Por debajo de lo esperado | P11: 3.88 | Q11: 3 | R11: 0 | S11: 44166 | T11: =IF(L11="Activo",(DATE(2024,1,1)-I11)/365,(J11-I11)/365) -> 3.5068493
A12: Camila Álvarez | B12: 1006020020 | C12: 3 | D12: 5280 | E12: Técnico de Producción I | F12: 31486 | G12: F | H12: Casado(a) | I12: 43709 | K12: N/A - Empleado | L12: Activo | M12: Producción | N12: Web de la Empresa | O12: Dentro de lo Esperado | P12: 5 | Q12: 5 | R12: 0 | S12: 44166 | T12: =IF(L12="Activo",(DATE(2024,1,1)-I12)/365,(J12-I12)/365) -> 4.3369863
A13: Cristina Ruiz | B13: 1408069882 | C13: 3 | D13: 3520 | E13: Técnico de Producción I | F13: 35091 | G13: F | H13: Soltero | I13: 44061 | K13: N/A - Empleado | L13: Activo | M13: Producción | N13: Feria de empleo | O13: Dentro de lo Esperado | P13: 3.99 | Q13: 3 | R13: 0 | S13: 44166 | T13: =IF(L13="Activo",(DATE(2024,1,1)-I13)/365,(J13-I13)/365) -> 3.3726027
... A22: Julio Acosta | B22: 1106026579 | C22: 3 | D22: 3300 | E22: Técnico de Producción I | F22: 30821 | G22: M | H22: Casado(a) | I22: 43502 | K22: N/A - Empleado | L22: Activo | M22: Producción | N22: Web de la Empresa | O22: Dentro de lo Esperado | P22: 5 | Q22: 3 | R22: 0 | S22: 44166 | T22: =IF(L22="Activo",(DATE(2024,1,1)-I22)/365,(J22-I22)/365) -> 4.9041096
A23: Maite Benítez | B23: 1201431438 | C23: 3 | D23: 4400 | E23: Técnico de Producción I | F23: 28437 | G23: F | H23: Soltero | I23: 43596 | K23: N/A - Empleado | L23: Activo | M23: Producción | N23: Web de empleo | O23: Dentro de lo Esperado | P23: 2.32 | Q23: 3 | R23: 0 | S23: 44166 | T23: =IF(L23="Activo",(DATE(2024,1,1)-I23)/365,(J23-I23)/365) -> 4.6465753
A24: Lucas Cabrera | B24: 1304055987 | C24: 3 | D24: 3740 | E24: Técnico de Producción I | F24: 33492 | G24: M | H24: Casado(a) | I24: 43715 | K24: N/A - Empleado | L24: Activo | M24: Producción | N24: Web de empleo | O24: Dentro de lo Esperado | P24: 5 | Q24: 5 | R24: 0 | S24: 44166 | T24: =IF(L24="Activo",(DATE(2024,1,1)-I24)/365,(J24-I24)/365) -> 4.3205479
A25: Inxgel Domínguez | B25: 1401064327 | C25: 3 | D25: 4400 | E25: Técnico de Producción I | F25: 30276 | G25: F | H25: Casado(a) | I25: 43250 | K25: N/A - Empleado | L25: Activo | M25: Producción | N25: Feria de empleo | O25: Dentro de lo Esperado | P25: 5 | Q25: 4 | R25: 0 | S25: 44166 | T25: =IF(L25="Activo",(DATE(2024,1,1)-I25)/365,(J25-I25)/365) -> 5.5945205
A26: Natalia Peralta | B26: 1203032357 | C26: 3 | D26: 4180 | E26: Técnico de Producción I | F26: 32695 | G26: F | H26: Soltero | I26: 44049 | K26: N/A - Empleado | L26: Activo | M26: Producción | N26: Indicación de empleados | O26: Dentro de lo Esperado | P26: 2.79 | Q26: 5 | R26: 0 | S26: 44166 | T26: =IF(L26="Activo",(DATE(2024,1,1)-I26)/365,(J26-I26)/365) -> 3.4054795
A27: Gonzalo Suárez | B27: 1001735072 | C27: 3 | D27: 3740 | E27: Técnico de Producción I | F27: 31738 | G27: M | H27: Soltero | I27: 41769 | K27: N/A - Empleado | L27: Activo | M27: Producción | N27: Web de empleo | O27: Dentro de lo Esperado | P27: 3.66 | Q27: 3 | R27: 0 | S27: 44166 | T27: =IF(L27="Activo",(DATE(2024,1,1)-I27)/365,(J27-I27)/365) -> 9.6520548
A28: Rocío Figueroa | B28: 710007555 | C28: 3 | D28: 3740 | E28: Técnico de Producción I | F28: 28986 | G28: F | H28: Soltero | I28: 44347 | K28: N/A - Empleado | L28: Activo | M28: Producción | N28: Web de empleo | O28: Dentro de lo Esperado | P28: 5 | Q28: 4 | R28: 0 | S28: 44166 | T28: =IF(L28="Activo",(DATE(2024,1,1)-I28)/365,(J28-I28)/365) -> 2.5890411
A29: Tamara Correa | B29: 1012023152 | C29: 2 | D29: 4840 | E29: Técnico de Producción I | F29: 32277 | G29: F | H29: Soltero | I29: 44243 | K29: N/A - Empleado | L29: Activo | M29: Producción | N29: Web de empleo | O29: Por debajo de lo esperado | P29: 2.44 | Q29: 3 | R29: 0 | S29: 44166 | T29: =IF(L29="Activo",(DATE(2024,1,1)-I29)/365,(J29-I29)/365) -> 2.8739726
A30: Melina Arias | B30: 1211051232 | C30: 3 | D30: 3300 | E30: Técnico de Producción I | F30: 30544 | G30: F | H30: Soltero | I30: 44467 | K30: N/A - Empleado | L30: Activo | M30: Producción | N30: Feria de empleo | O30: Dentro de lo Esperado | P30: 1.24 | Q30: 5 | R30: 0 | S30: 44166 | T30: =IF(L30="Activo",(DATE(2024,1,1)-I30)/365,(J30-I30)/365) -> 2.260274
A31: Francis Ponce | B31: 1011022883 | C31: 3 | D31: 4620 | E31: Técnico de Producción I | F31: 34238 | G31: F | H31: Casado(a) | I31: 42186 | K31: N/A - Empleado | L31: Activo | M31: Producción | N31: Web de la Empresa | O31: Dentro de lo Esperado | P31: 4.84 | Q31: 5 | R31: 0 | S31: 44166 | T31: =IF(L31="Activo",(DATE(2024,1,1)-I31)/365,(J31-I31)/365) -> 8.509589
A32: Daniela Moya | B32: 1403066194 | C32: 3 | D32: 4840 | E32: Técnico de Producción I | F32: 27693 | G32: F | H32: Soltero | I32: 43193 | K32: N/A - Empleado | L32: Activo | M32: Producción | N32: Web de empleo | O32: Dentro de lo Esperado | P32: 5 | Q32: 5 | R32: 0 | S32: 44166 | T32: =IF(L32="Activo",(DATE(2024,1,1)-I32)/365,(J32-I32)/365) -> 5.7506849
A33: Alejandra Ibáñez | B33: 1305057282 | C33: 3 | D33: 4290 | E33: Técnico de Producción I | F33: 31016 | G33: F | H33: Soltero | I33: 44534 | K33: N/A - Empleado | L33: Activo | M33: Producción | N33: Web de empleo | O33: Dentro de lo Esperado | P33: 2.73 | Q33: 4 | R33: 0 | S33: 44166 | T33: =IF(L33="Activo",(DATE(2024,1,1)-I33)/365,(J33-I33)/365) -> 2.0767123
A34: Micaela Soto | B34: 1001109612 | C34: 3 | D34: 3300 | E34: Técnico de Producción I | F34: 30446 | G34: F | H34: Casado(a) | I34: 43502 | K34: N/A - Empleado | L34: Activo | M34: Producción | N34: Web de la Empresa | O34: Dentro de lo Esperado | P34: 5 | Q34: 3 | R34: 0 | S34: 44166 | T34: =IF(L34="Activo",(DATE(2024,1,1)-I34)/365,(J34-I34)/365) -> 4.9041096
A35: Emanuel Luna | B35: 1406068241 | C35: 3 | D35: 4620 | E35: Técnico de Producción I | F35: 31816 | G35: M | H35: Casado(a) | I35: 43599 | K35: N/A - Empleado | L35: Activo | M35: Producción | N35: Web de empleo | O35: Dentro de lo Esperado | P35: 1.83 | Q35: 3 | R35: 0 | S35: 44166 | T35: =IF(L35="Activo",(DATE(2024,1,1)-I35)/365,(J35-I35)/365) -> 4.6383562
... A54: Paola Maidana | B54: 1408069539 | C54: 3 | D54: 3740 | E54: Técnico de Producción I | F54: 35598 | G54: F | H54: Soltero | I54: 44145 | K54: N/A - Empleado | L54: Activo | M54: Producción | N54: Web de empleo | O54: Dentro de lo Esperado | P54: 1.94 | Q54: 5 | R54: 0 | S54: 44166 | T54: =IF(L54="Activo",(DATE(2024,1,1)-I54)/365,(J54-I54)/365) -> 3.1424658
A55: Kevin Barrios | B55: 1002021900 | C55: 3 | D55: 4180 | E55: Técnico de Producción I | F55: 32598 | G55: M | H55: Soltero | I55: 43690 | K55: N/A - Empleado | L55: Activo | M55: Producción | N55: Web de la Empresa | O55: Dentro de lo Esperado | P55: 4.17 | Q55: 4 | R55: 0 | S55: 44166 | T55: =IF(L55="Activo",(DATE(2024,1,1)-I55)/365,(J55-I55)/365) -> 4.3890411
A56: Roque Páez | B56: 1304055683 | C56: 3 | D56: 3080 | E56: Técnico de Producción I | F56: 30234 | G56: M | H56: Soltero | I56: 44243 | K56: N/A - Empleado | L56: Activo | M56: Producción | N56: Feria de empleo | O56: Dentro de lo Esperado | P56: 2.79 | Q56: 3 | R56: 0 | S56: 44166 | T56: =IF(L56="Activo",(DATE(2024,1,1)-I56)/365,(J56-I56)/365) -> 2.8739726
A57: Ana Duarte | B57: 1209049259 | C57: 3 | D57: 3740 | E57: Técnico de Producción I | F57: 33425 | G57: F | H57: Soltero | I57: 44347 | K57: N/A - Empleado | L57: Activo | M57: Producción | N57: Web de empleo | O57: Dentro de lo Esperado | P57: 2.55 | Q57: 4 | R57: 0 | S57: 44166 | T57: =IF(L57="Activo",(DATE(2024,1,1)-I57)/365,(J57-I57)/365) -> 2.5890411
A58: Andrea Gallardo | B58: 1307059944 | C58: 3 | D58: 3740 | E58: Técnico de Producción I | F58: 28755 | G58: F | H58: Casado(a) | I58: 42850 | K58: N/A - Empleado | L58: Activo | M58: Producción | N58: Web de empleo | O58: Dentro de lo Esperado | P58: 2.72 | Q58: 3 | R58: 0 | S58: 44166 | T58: =IF(L58="Activo",(DATE(2024,1,1)-I58)/365,(J58-I58)/365) -> 6.690411
A59: Malena Roldán | B59: 1501071909 | C59: 3 | D59: 5390 | E59: Técnico de Producción I | F59: 25600 | G59: F | H59: Soltero | I59: 44145 | K59: N/A - Empleado | L59: Activo | M59: Producción | N59: Indicación de empleados | O59: Dentro de lo Esperado | P59: 3.73 | Q59: 3 | R59: 0 | S59: 44166 | T59: =IF(L59="Activo",(DATE(2024,1,1)-I59)/365,(J59-I59)/365) -> 3.1424658
A60: Yamil Reynoso | B60: 1104025414 | C60: 3 | D60: 3960 | E60: Técnico de Producción I | F60: 31154 | G60: M | H60: Soltero | I60: 44049 | K60: N/A - Empleado | L60: Activo | M60: Producción | N60: Feria de empleo | O60: Dentro de lo Esperado | P60: 2.61 | Q60: 4 | R60: 0 | S60: 44166 | T60: =IF(L60="Activo",(DATE(2024,1,1)-I60)/365,(J60-I60)/365) -> 3.4054795
A61: Estela Cáceres | B61: 1503072857 | C61: 3 | D61: 4620 | E61: Técnico de Producción I | F61: 26013 | G61: F | H61: Soltero | I61: 44103 | K61: N/A - Empleado | L61: Activo | M61: Producción | N61: Indicación de empleados | O61: Dentro de lo Esperado | P61: 2.05 | Q61: 5 | R61: 0 | S61: 44166 | T61: =IF(L61="Activo",(DATE(2024,1,1)-I61)/365,(J61-I61)/365) -> 3.2575342
A62: Karen Escobar | B62: 909015167 | C62: 3 | D62: 5280 | E62: Técnico de Producción I | F62: 33784 | G62: F | H62: Casado(a) | I62: 44012 | K62: N/A - Empleado | L62: Activo | M62: Producción | N62: Web de empleo | O62: Dentro de lo Esperado | P62: 3.93 | Q62: 3 | R62: 0 | S62: 44166 | T62: =IF(L62="Activo",(DATE(2024,1,1)-I62)/365,(J62-I62)/365) -> 3.5068493
A63: Lucía Bravo | B63: 1111030244 | C63: 3 | D63: 3080 | E63: Técnico de Producción I | F63: 32013 | G63: F | H63: Soltero | I63: 43373 | K63: N/A - Empleado | L63: Activo | M63: Producción | N63: Indicación de empleados | O63: Dentro de lo Esperado | P63: 1.05 | Q63: 4 | R63: 0 | S63: 44166 | T63: =IF(L63="Activo",(DATE(2024,1,1)-I63)/365,(J63-I63)/365) -> 5.2575342
A64: Gregorio Salas | B64: 1409070522 | C64: 4 | D64: 4400 | E64: Técnico de Producción I | F64: 32421 | G64: M | H64: Soltero | I64: 43226 | K64: N/A - Empleado | L64: Activo | M64: Producción | N64: Web de la Empresa | O64: Por encima de lo Esperado | P64: 2.51 | Q64: 5 | R64: 0 | S64: 44166 | T64: =IF(L64="Activo",(DATE(2024,1,1)-I64)/365,(J64-I64)/365) -> 5.660274
A65: Ivanna Montoya | B65: 1208048062 | C65: 3 | D65: 3520 | E65: Técnico de Producción I | F65: 20485 | G65: F | H65: Soltero | I65: 44467 | K65: N/A - Empleado | L65: Activo | M65: Producción | N65: Web de empleo | O65: Dentro de lo Esperado | P65: 5 | Q65: 4 | R65: 0 | S65: 44166 | T65: =IF(L65="Activo",(DATE(2024,1,1)-I65)/365,(J65-I65)/365) -> 2.260274
A66: Marisol Antúnez | B66: 1311063172 | C66: 3 | D66: 4345 | E66: Técnico de Producción I | F66: 33879 | G66: F | H66: Soltero | I66: 45084 | K66: N/A - Empleado | L66: Activo | M66: Producción | N66: Web de empleo | O66: Dentro de lo Esperado | P66: 4.12 | Q66: 5 | R66: 0 | S66: 44166 | T66: =IF(L66="Activo",(DATE(2024,1,1)-I66)/365,(J66-I66)/365) -> 0.56986301
...

Sheet Análisis - Respuestas
A1: PEOPLE ANALYTICS
A2: Evaluación de Empleados Activos
A4: 1 - ¿Cuántos empleados activos hay actualmente en la empresa?
B6: Deparmento | C6: Qtd | D6: % | F6: Status | G6: Qtd
B7: Producción | C7: =COUNTIFS(BD!$M:$M,'Análisis - Respuestas'!B7,BD!$L:$L,"Activo") -> 125 | D7: =C7/$C$11 -> 0.60386473 | F7: Activo | G7: =COUNTIFS(BD!$L:$L,F7) -> 207
B8: Ventas | C8: =COUNTIFS(BD!$M:$M,'Análisis - Respuestas'!B8,BD!$L:$L,"Activo") -> 27 | D8: =C8/$C$11 -> 0.13043478 | F8: Despedido | G8: =COUNTIFS(BD!$L:$L,F8) -> 24
B9: Administrativo | C9: =COUNTIFS(BD!$M:$M,'Análisis - Respuestas'!B9,BD!$L:$L,"Activo") -> 8 | D9: =C9/$C$11 -> 0.038647343 | F9: Solicito despido | G9: =COUNTIFS(BD!$L:$L,F9) -> 79
B10: TI | C10: =COUNTIFS(BD!$M:$M,'Análisis - Respuestas'!B10,BD!$L:$L,"Activo") -> 47 | D10: =C10/$C$11 -> 0.22705314 | F10: Total | G10: =SUM(G7:G9) -> 310
B11: Total | C11: =SUM(C7:C10) -> 207 | D11: =SUM(D7:D10) -> 1
A14: 2 - ¿Cuál es el costo de nómina mensual de esta empresa? / ¿Qué porcentaje de diversidad maneja la empresa?
B16: Empleados Activos | C16: Qtd | D16: % | E16: Costo mensual
B17: Femenino | C17: =COUNTIFS(BD!$G:$G,"F",BD!$L:$L,"Activo") -> 116 | D17: =C17/$C$20 -> 0.56038647 | E17: =SUMIFS(BD!$D:$D,BD!$L:$L,"Activo",BD!$G:$G,"F") -> 755850
B18: Masculino | C18: =COUNTIFS(BD!$G:$G,"M",BD!$L:$L,"Activo") -> 89 | D18: =C18/$C$20 -> 0.42995169 | E18: =SUMIFS(BD!$D:$D,BD!$L:$L,"Activo",BD!$G:$G,"M") -> 612864
B19: No Binario | C19: =COUNTIFS(BD!$G:$G,"NB",BD!$L:$L,"Activo") -> 2 | D19: =C19/$C$20 -> 0.0096618357 | E19: =SUMIFS(BD!$D:$D,BD!$L:$L,"Activo",BD!$G:$G,"NB") -> 24156
B20: Total | C20: =SUM(C17:C19) -> 207 | D20: =SUM(D17:D19) -> 1 | E20: =SUM(E17:E19) -> 1392870
A23: 3 - ¿Cuál es la principal fuente de contratación de la empresa? / 4 - De los miembros activos, ¿Qué porcentaje se basó en referencias de empleados?
B25: Fuente Reclutamiento | C25: Total BD | D25: Total Activos | E25: % Activos
B26: Web de la Empresa | C26: =COUNTIFS(BD!$N:$N,'Análisis - Respuestas'!B26) -> 61 | D26: =COUNTIFS(BD!$N:$N,'Análisis - Respuestas'!B26,BD!$L:$L,"Activo") -> 32 | E26: =D26/$D$30 -> 0.15458937
B27: Indicación de empleados | C27: =COUNTIFS(BD!$N:$N,'Análisis - Respuestas'!B27) -> 54 | D27: =COUNTIFS(BD!$N:$N,'Análisis - Respuestas'!B27,BD!$L:$L,"Activo") -> 43 | E27: =D27/$D$30 -> 0.20772947
B28: Web de empleo | C28: =COUNTIFS(BD!$N:$N,'Análisis - Respuestas'!B28) -> 129 | D28: =COUNTIFS(BD!$N:$N,'Análisis - Respuestas'!B28,BD!$L:$L,"Activo") -> 87 | E28: =D28/$D$30 -> 0.42028986
B29: Feria de empleo | C29: =COUNTIFS(BD!$N:$N,'Análisis - Respuestas'!B29) -> 66 | D29: =COUNTIFS(BD!$N:$N,'Análisis - Respuestas'!B29,BD!$L:$L,"Activo") -> 45 | E29: =D29/$D$30 -> 0.2173913
B30: Total | C30: =SUM(C26:C29) -> 310 | D30: =SUM(D26:D29) -> 207 | E30: =SUM(E26:E29) -> 1
A33: 5 - Según la última evaluación de desempeño, ¿Qué porcentaje de empleados activos se desempeñó por debajo de las expectativas? | L33: Siempre es bueno investigar o traer información adicional
B35: Registro de Rendimiento | C35: Activos | D35: % Activos
B36: Por encima de lo Esperado | C36: =COUNTIFS(BD!$O:$O, 'Análisis - Respuestas'!B36,BD!$L:$L,"Activo") -> 29 | D36: =C36/$C$39 -> 0.14009662
B37: Dentro de lo Esperado | C37: =COUNTIFS(BD!$O:$O, 'Análisis - Respuestas'!B37,BD!$L:$L,"Activo") -> 162 | D37: =C37/$C$39 -> 0.7826087
B38: Por debajo de lo esperado | C38: =COUNTIFS(BD!$O:$O, 'Análisis - Respuestas'!B38,BD!$L:$L,"Activo") -> 16 | D38: =C38/$C$39 -> 0.077294686
B39: Total | C39: =SUM(C36:C38) -> 207 | D39: =SUM(D36:D38) -> 1
A42: 6 - De los profesionales en activo, ¿Cuál es el promedio de años que llevan trabajando en esta empresa?
B44: Status | C44: Tiempo Medio Años 24
B45: Activo | C45: =AVERAGEIF(BD!$L:$L,'Análisis - Respuestas'!B45,BD!$T:$T) -> 3.3527099
B46: Despedido | C46: =AVERAGEIF(BD!$L:$L,'Análisis - Respuestas'!B46,BD!$T:$T) -> 1.7017123
B47: Solicito despido | C47: =AVERAGEIF(BD!$L:$L,'Análisis - Respuestas'!B47,BD!$T:$T) -> 2.4492804
B48: Total | C48: =AVERAGE(C45:C47) -> 2.5012342
A51: 7 - ¿Qué departamento representó el mayor nivel de satisfacción en la última encuesta realizada? (Considerando sólo los empleados activos).
B53: Deparmento | C53: Indice de Satisfacción*
B54: Producción | C54: =AVERAGEIFS(BD!$Q:$Q,BD!$L:$L,"Activo",BD!$M:$M,'Análisis - Respuestas'!B54) -> 3.8232
B55: Ventas | C55: =AVERAGEIFS(BD!$Q:$Q,BD!$L:$L,"Activo",BD!$M:$M,'Análisis - Respuestas'!B55) -> 3.8888889
B56: Administrativo | C56: =AVERAGEIFS(BD!$Q:$Q,BD!$L:$L,"Activo",BD!$M:$M,'Análisis - Respuestas'!B56) -> 3.5
B57: TI | C57: =AVERAGEIFS(BD!$Q:$Q,BD!$L:$L,"Activo",BD!$M:$M,'Análisis - Respuestas'!B57) -> 4.0425532
...
